<?xml version="1.0"?>
<robot xmlns:xacro="http://www.ros.org/wiki/xacro" name="m">
  <xacro:property name="L1" value="1.0"/>
  <xacro:property name="L2" value="0.5"/>
  <xacro:property name="L3" value="0.2"/>
  <xacro:property name="rho" value="0.5"/>
  
  
  <gazebo>
    <plugin name="gazebo_ros_control" filename="libgazebo_ros_control.so">
      <robotNamespace>/rrr</robotNamespace>
    </plugin>
  </gazebo>


  <gazebo reference="">
    <self_collide>1</self_collide>
  </gazebo>
  <link name="world">
    <inertial>
      <mass value="1.0" />
      <inertia ixx="1.0" ixy="0.0" ixz="0.0" iyy="1.0" iyz="0.0" izz="1.0" />
    </inertial>
  </link>

  <link name="link0">
    <visual>
      <geometry>
        <sphere radius="0.05"/>
      </geometry>
      <origin xyz="0 0 0" rpy="0 1.5707963 0"/>
    </visual>
    <inertial>
      <mass value="1.0" />
      <inertia ixx="1.0" ixy="0.0" ixz="0.0" iyy="1.0" iyz="0.0" izz="1.0" />
    </inertial>
  </link>

  <link name="link1">
    <visual>
      <geometry>
  	<cylinder length="${L1}" radius="0.02"/>
      </geometry>
      <origin xyz="${L1/2} 0 0" rpy="0 1.5707963 0"/>
    </visual>
    <collision>
      <geometry>
        <cylinder length="${L1-0.1}" radius="0.05"/>
      </geometry>
      <origin xyz="${L1/2} 0 0" rpy="0 1.5707963 0"/>
    </collision>
    <inertial>
      <origin xyz="0 0 0" rpy="0 0 0"/>
      <mass value="${rho*L1}"/>
      <inertia ixx="${(rho*L1*L1*L1)/12}"  ixy="0"  ixz="0" iyy="0" iyz="0" izz="${(rho*L1*L1*L1)/3}" />
    </inertial>
  </link>

  <link name="link2">
    <visual>
      <geometry>
        <cylinder length="${L2}" radius="0.02"/>
      </geometry>
      <origin xyz="${L2/2} 0 0" rpy="0 1.5707963 0"/>
    </visual>
    <collision>
      <geometry>
        <cylinder length="${L2-0.1}" radius="0.05"/>
      </geometry>
      <origin xyz="${L2/2} 0 0" rpy="0 1.5707963 0"/>
    </collision>
    <inertial>
      <origin xyz="0 0 0" rpy="0 0 0"/>
      <mass value="${rho*L2}"/>
      <inertia ixx="${(rho*L2*L2*L2)/12}"  ixy="0"  ixz="0" iyy="0" iyz="0" izz="${(rho*L2*L2*L2)/3}" />
    </inertial>
  </link>

  <link name="link3">
    <visual>
      <geometry>
        <cylinder length="${L3}" radius="0.02"/>
      </geometry>
      <origin xyz="${L3/2} 0 0" rpy="0 1.5707963 0"/>
    </visual>
    <collision>
      <geometry>
        <cylinder length="${L3-0.1}" radius="0.05"/>
      </geometry>
      <origin xyz="${L3/2} 0 0" rpy="0 1.5707963 0"/>
    </collision>
    <inertial>
      <origin xyz="0 0 0" rpy="0 0 0"/>
      <mass value="${rho*L3}"/>
      <inertia ixx="${(rho*L3*L3*L3)/12}"  ixy="0"  ixz="0" iyy="0" iyz="0" izz="${(rho*L3*L3*L3)/3}" />
   </inertial>
  </link>

  <joint name="fixed" type="fixed">
    <origin xyz="0 0 0" rpy="0 0 0"/>
    <parent link="world"/>
    <child link="link0"/>
  </joint>

  <joint name="joint1" type="continuous">
    <origin xyz="0 0 0" rpy="0 0 0"/>
    <axis xyz="0 0 1" />
    <dynamics damping="0.5"/>
    <parent link="link0"/>
    <child link="link1"/>
  </joint>

  <joint name="joint2" type="continuous">
    <origin xyz="${L1} 0 0" rpy="0 0 0"/>
    <axis xyz="0 0 1" />
    <dynamics damping="0.5"/>
    <parent link="link1"/>
    <child link="link2"/>
  </joint>

  <joint name="joint3" type="continuous">
    <origin xyz="${L2} 0 0" rpy="0 0 0"/>
    <axis xyz="0 0 1" />
    <dynamics damping="0.5"/>
    <parent link="link2"/>
    <child link="link3"/>
  </joint>

  <transmission name="tran1">
    <type>transmission_interface/SimpleTransmission</type>
    <joint name="joint1">
      <hardwareInterface>hardware_interface/EffortJointInterface</hardwareInterface>
    </joint>
    <actuator name="motor1">
      <hardwareInterface>hardware_interface/EffortJointInterface</hardwareInterface>
      <mechanicalReduction>1</mechanicalReduction>
    </actuator>
  </transmission>

  <transmission name="tran2">
    <type>transmission_interface/SimpleTransmission</type>
    <joint name="joint2">
      <hardwareInterface>hardware_interface/EffortJointInterface</hardwareInterface>
    </joint>
    <actuator name="motor2">
      <hardwareInterface>hardware_interface/EffortJointInterface</hardwareInterface>
      <mechanicalReduction>1</mechanicalReduction>
    </actuator>
  </transmission>

  <transmission name="tran3">
    <type>transmission_interface/SimpleTransmission</type>
    <joint name="joint3">
      <hardwareInterface>hardware_interface/EffortJointInterface</hardwareInterface>
    </joint>
    <actuator name="motor3">
      <hardwareInterface>hardware_interface/EffortJointInterface</hardwareInterface>
      <mechanicalReduction>1</mechanicalReduction>
    </actuator>
  </transmission>
</robot>
